2024-05-04 14:28:31,486 - ERROR - No error handlers are registered, logging exception.
Traceback (most recent call last):
  File "/Users/danielgnagi/Library/Python/3.9/lib/python/site-packages/telegram/ext/_application.py", line 1277, in process_update
    await coroutine
  File "/Users/danielgnagi/Library/Python/3.9/lib/python/site-packages/telegram/ext/_handlers/basehandler.py", line 157, in handle_update
    return await self.callback(update, context)
  File "/Users/danielgnagi/Documents/altpapierBot/altpapierbot.py", line 39, in registration_en
    await send_registration_error(culture, update)
  File "/Users/danielgnagi/Documents/altpapierBot/altpapierbot.py", line 69, in send_registration_error
    valid_entries = ", ".join(str(code.value) for code in VALID_POSTAL_CODES)
  File "/Users/danielgnagi/Documents/altpapierBot/altpapierbot.py", line 69, in <genexpr>
    valid_entries = ", ".join(str(code.value) for code in VALID_POSTAL_CODES)
AttributeError: 'int' object has no attribute 'value'
2024-05-04 14:29:27,894 - ERROR - No error handlers are registered, logging exception.
Traceback (most recent call last):
  File "/Users/danielgnagi/Library/Python/3.9/lib/python/site-packages/telegram/ext/_application.py", line 1277, in process_update
    await coroutine
  File "/Users/danielgnagi/Library/Python/3.9/lib/python/site-packages/telegram/ext/_handlers/basehandler.py", line 157, in handle_update
    return await self.callback(update, context)
  File "/Users/danielgnagi/Documents/altpapierBot/altpapierbot.py", line 39, in registration_en
    await send_registration_error(culture, update)
  File "/Users/danielgnagi/Documents/altpapierBot/altpapierbot.py", line 69, in send_registration_error
    valid_entries = ", ".join(str(code.value) for code in VALID_POSTAL_CODES)
  File "/Users/danielgnagi/Documents/altpapierBot/altpapierbot.py", line 69, in <genexpr>
    valid_entries = ", ".join(str(code.value) for code in VALID_POSTAL_CODES)
AttributeError: 'int' object has no attribute 'value'
2024-05-04 14:31:09,199 - ERROR - No error handlers are registered, logging exception.
Traceback (most recent call last):
  File "/Users/danielgnagi/Library/Python/3.9/lib/python/site-packages/telegram/ext/_application.py", line 1277, in process_update
    await coroutine
  File "/Users/danielgnagi/Library/Python/3.9/lib/python/site-packages/telegram/ext/_handlers/basehandler.py", line 157, in handle_update
    return await self.callback(update, context)
  File "/Users/danielgnagi/Documents/altpapierBot/altpapierbot.py", line 40, in registration_en
    valid_entries = ", ".join(str(code.value) for code in VALID_POSTAL_CODES)
  File "/Users/danielgnagi/Documents/altpapierBot/altpapierbot.py", line 40, in <genexpr>
    valid_entries = ", ".join(str(code.value) for code in VALID_POSTAL_CODES)
AttributeError: 'int' object has no attribute 'value'
2024-05-04 14:32:15,268 - ERROR - No error handlers are registered, logging exception.
Traceback (most recent call last):
  File "/Users/danielgnagi/Library/Python/3.9/lib/python/site-packages/telegram/ext/_application.py", line 1277, in process_update
    await coroutine
  File "/Users/danielgnagi/Library/Python/3.9/lib/python/site-packages/telegram/ext/_handlers/basehandler.py", line 157, in handle_update
    return await self.callback(update, context)
  File "/Users/danielgnagi/Documents/altpapierBot/altpapierbot.py", line 55, in registration_en
    rf"{message}{new_subscription.area}",
AttributeError: 'coroutine' object has no attribute 'area'
2024-05-04 14:33:07,256 - ERROR - No error handlers are registered, logging exception.
Traceback (most recent call last):
  File "/Users/danielgnagi/Library/Python/3.9/lib/python/site-packages/telegram/ext/_application.py", line 1277, in process_update
    await coroutine
  File "/Users/danielgnagi/Library/Python/3.9/lib/python/site-packages/telegram/ext/_handlers/basehandler.py", line 157, in handle_update
    return await self.callback(update, context)
  File "/Users/danielgnagi/Documents/altpapierBot/altpapierbot.py", line 33, in registration_en
    valid_entries = ", ".join(str(code.value) for code in VALID_POSTAL_CODES)
  File "/Users/danielgnagi/Documents/altpapierBot/altpapierbot.py", line 33, in <genexpr>
    valid_entries = ", ".join(str(code.value) for code in VALID_POSTAL_CODES)
AttributeError: 'int' object has no attribute 'value'
